'apt' is not recognized as an internal or external command,
operable program or batch file.
'apt' is not recognized as an internal or external command,
operable program or batch file.
Requirement already satisfied: selenium in c:\users\user\anaconda3\lib\site-packages (4.1.5)
Requirement already satisfied: trio-websocket~=0.9 in c:\users\user\anaconda3\lib\site-packages (from selenium) (0.9.2)
Requirement already satisfied: trio~=0.17 in c:\users\user\anaconda3\lib\site-packages (from selenium) (0.20.0)
Requirement already satisfied: urllib3[secure,socks]~=1.26 in c:\users\user\anaconda3\lib\site-packages (from selenium) (1.26.9)
Requirement already satisfied: async-generator>=1.9 in c:\users\user\anaconda3\lib\site-packages (from trio~=0.17->selenium) (1.10)
Requirement already satisfied: cffi>=1.14 in c:\users\user\anaconda3\lib\site-packages (from trio~=0.17->selenium) (1.15.0)
Requirement already satisfied: sniffio in c:\users\user\anaconda3\lib\site-packages (from trio~=0.17->selenium) (1.2.0)
Requirement already satisfied: idna in c:\users\user\anaconda3\lib\site-packages (from trio~=0.17->selenium) (3.3)
Requirement already satisfied: sortedcontainers in c:\users\user\anaconda3\lib\site-packages (from trio~=0.17->selenium) (2.4.0)
Requirement already satisfied: outcome in c:\users\user\anaconda3\lib\site-packages (from trio~=0.17->selenium) (1.1.0)
Requirement already satisfied: attrs>=19.2.0 in c:\users\user\anaconda3\lib\site-packages (from trio~=0.17->selenium) (21.4.0)
Requirement already satisfied: pycparser in c:\users\user\anaconda3\lib\site-packages (from cffi>=1.14->trio~=0.17->selenium) (2.21)
Requirement already satisfied: wsproto>=0.14 in c:\users\user\anaconda3\lib\site-packages (from trio-websocket~=0.9->selenium) (1.1.0)
Requirement already satisfied: cryptography>=1.3.4 in c:\users\user\anaconda3\lib\site-packages (from urllib3[secure,socks]~=1.26->selenium) (3.4.8)
Requirement already satisfied: pyOpenSSL>=0.14 in c:\users\user\anaconda3\lib\site-packages (from urllib3[secure,socks]~=1.26->selenium) (21.0.0)
Requirement already satisfied: certifi in c:\users\user\anaconda3\lib\site-packages (from urllib3[secure,socks]~=1.26->selenium) (2021.10.8)
Requirement already satisfied: PySocks!=1.5.7,<2.0,>=1.5.6 in c:\users\user\anaconda3\lib\site-packages (from urllib3[secure,socks]~=1.26->selenium) (1.7.1)
Requirement already satisfied: six>=1.5.2 in c:\users\user\anaconda3\lib\site-packages (from pyOpenSSL>=0.14->urllib3[secure,socks]~=1.26->selenium) (1.16.0)
Requirement already satisfied: h11<1,>=0.9.0 in c:\users\user\anaconda3\lib\site-packages (from wsproto>=0.14->trio-websocket~=0.9->selenium) (0.13.0)
The thread 'MainThread' (0x1) has exited with code 0 (0x0).
Loaded 'suppliers.execute_scenaries'
Loaded 'suppliers'
Loaded '__main__'
Loaded 'threading'
The program 'python.exe' has exited with code 0 (0x0).
